<mujoco model="Gen3Lite">
  <compiler angle="radian"/>
  <option gravity="0 0 0"/> 

  
  <asset>
    <mesh name="BASE" file="BASE.STL"/>
    <mesh name="SHOULDER" file="SHOULDER.STL"/>
    <mesh name="ARM" file="ARM.STL"/>
    <mesh name="FOREARM" file="FOREARM.STL"/>
    <mesh name="LOWER_WRIST" file="LOWER_WRIST.STL"/>
    <mesh name="UPPER_WRIST" file="UPPER_WRIST.STL"/>
  </asset>
  <worldbody>
    <geom type="mesh" mesh="BASE"/>
    <body name="SHOULDER" pos="0 0 0.12825">
      <inertial pos="2.477e-05 0.0221353 0.0993769" quat="0.972429 0.233194 -0.000430944 0.00108761" mass="0.959744" diaginertia="0.00165947 0.00158128 0.000717195"/>
      <joint name="J0" pos="0 0 0" axis="0 0 1" range="-2.76 2.76"/>
      <geom type="mesh" mesh="SHOULDER" rgba="0.7 0.7 0.7 0.3"/>
      <site name="J0_sensor" pos="0 0 0" rgba="1 0 0 1"/>
      <body name="ARM" pos="0 -0.03 0.115" quat="0.707105 0.707108 0 0">
        <inertial pos="0.029983 0.211548 0.0453031" quat="0.534676 0.467794 -0.46336 0.529706" mass="1.17756" diaginertia="0.0115237 0.0114928 0.000839712"/>
        <joint name="J1" pos="0 0 0" axis="0 0 1" range="-2.76 2.76"/>
        <geom type="mesh" mesh="ARM" rgba="0.7 0.7 0.7 0.3"/>
        <site name="J1_sensor" pos="0 0 0" rgba="1 0 0 1"/>
        <body name="FOREARM" pos="0 0.28 0" quat="-3.67321e-06 -1 0 0">
          <inertial pos="0.0301559 0.0950221 0.0073555" quat="0.523543 0.49139 -0.473675 0.50997" mass="0.597677" diaginertia="0.00169754 0.00163253 0.000291376"/>
          <joint name="J2" pos="0 0 0" axis="0 0 1" range="-2.76 2.76"/>
          <geom type="mesh" mesh="FOREARM" rgba="0.7 0.7 0.7 0.3"/>
          <site name="J2_sensor" pos="0 0 0" rgba="1 0 0 1"/>
          <body name="LOWER_WRIST" pos="0 -0.14 0.02" quat="0.707105 0.707108 0 0">
            <inertial pos="0.00575149 0.0100044 0.0871921" quat="0.700403 -0.13124 -0.134345 0.688595" mass="0.526934" diaginertia="0.000785199 0.000756398 0.000275722"/>
            <joint name="J3" pos="0 0 0" axis="0 0 1" range="-2.67 2.67"/>
            <geom type="mesh" mesh="LOWER_WRIST" rgba="0.7 0.7 0.7 0.3"/>
            <site name="J3_sensor" pos="0 0 0" rgba="1 0 0 1"/>
            <body name="UPPER_WRIST" pos="0.0285 0 0.105" quat="0.707105 0 0.707108 0">
              <inertial pos="0.0805652 0.00980409 0.018728" quat="0.00431726 0.708285 -4.18922e-06 0.705913" mass="0.580973" diaginertia="0.00108466 0.00106374 0.000212638"/>
              <joint name="J4" pos="0 0 0" axis="0 0 1" range="-2.67 2.67"/>
              <geom type="mesh" mesh="UPPER_WRIST" rgba="0.7 0.7 0.7 0.3"/>
              <site name="J4_sensor" pos="0 0 0" rgba="1 0 0 1"/>
            </body>
          </body>
        </body>
      </body>
    </body>
  </worldbody>

  <sensor>
      <velocimeter name="J0_vel" site="J0_sensor"/>
      <accelerometer name="J0_acc" site="J0_sensor"/>
      <velocimeter name="J1_vel" site="J1_sensor"/>
      <accelerometer name="J1_acc" site="J1_sensor"/>
      <velocimeter name="J2_vel" site="J2_sensor"/>
      <accelerometer name="J2_acc" site="J2_sensor"/>
      <velocimeter name="J3_vel" site="J3_sensor"/>
      <accelerometer name="J3_acc" site="J3_sensor"/>
      <velocimeter name="J4_vel" site="J4_sensor"/>
      <accelerometer name="J4_acc" site="J4_sensor"/>
  </sensor>
</mujoco>
