<mujoco model="robros">
  <include file="model_base.xml"/>


  <compiler balanceinertia="true"/>
  <option gravity="0 0 0"/> 

  <actuator>
      <!-- <motor joint="Continuous_1" gear="100" name="Continuous_1"/>  -->
      <motor joint="Continuous_1" name="Continuous_1" ctrllimited="false"/>
      <motor joint="Continuous_2" name="Continuous_2" ctrllimited="false"/>
      <motor joint="Continuous_3" name="Continuous_3" ctrllimited="false"/>
      <motor joint="Continuous_4" name="Continuous_4" ctrllimited="false"/>
      <motor joint="Continuous_5" name="Continuous_5" ctrllimited="false"/>
      <motor joint="Continuous_6" name="Continuous_6" ctrllimited="false"/>
      <motor joint="Continuous_7" name="Continuous_7" ctrllimited="false"/>
  </actuator>


  <asset>
    <mesh name="base_link" file="/home/robros/catkin_ws/src/NewNew_description/urdf/base_link.stl" scale="0.001 0.001 0.001"/>
    <mesh name="link_1" file="/home/robros/catkin_ws/src/NewNew_description/urdf/One_Body_Link1_v1_v4_1.stl" scale="0.001 0.001 0.001"/>
    <mesh name="link_2" file="/home/robros/catkin_ws/src/NewNew_description/urdf/One_Body_Link2_v1_v1_1.stl" scale="0.001 0.001 0.001"/>
    <mesh name="link_3" file="/home/robros/catkin_ws/src/NewNew_description/urdf/One_Body_Link3_v1_v1_1.stl" scale="0.001 0.001 0.001"/>
    <mesh name="link_4" file="/home/robros/catkin_ws/src/NewNew_description/urdf/One_Body_Link4_v1_v1_1.stl" scale="0.001 0.001 0.001"/>
    <mesh name="link_5" file="/home/robros/catkin_ws/src/NewNew_description/urdf/One_Body_Link5_v1_v1_1.stl" scale="0.001 0.001 0.001"/>
    <mesh name="link_6" file="/home/robros/catkin_ws/src/NewNew_description/urdf/One_Body_Link6_v1_v1_1.stl" scale="0.001 0.001 0.001"/>
    <mesh name="link_7" file="/home/robros/catkin_ws/src/NewNew_description/urdf/One_Body_Link7_v1_v1_1.stl" scale="0.001 0.001 0.001"/>
  </asset>
  <worldbody>
    
    <body name="base_link" pos="-0.048 -0.048 -1.35">
    <geom type="mesh" contype="0" conaffinity="0" group="1" mesh="base_link"/>
      
      <body name="link_1" pos="0.048764 0.045177 1.35004">
        <inertial pos="0.000460412 0.0845415 -9.53515e-05" quat="0.706114 0.70807 -0.00440356 -0.00453222" mass="8.37301" diaginertia="0.0312281 0.0293191 0.0116017"/>
        <joint name="Continuous_1" pos="0 0 0" axis="0 -1 0" class="default_joint"/>
        <geom pos="-0.048764 -0.045177 -1.35004" class="cls" mesh="link_1" name="link viz_1"/>
        <geom pos="-0.048764 -0.045177 -1.35004" class="viz" mesh="link_1" name="link_col_1"/>
        
        <body name="link_2" pos="0.0315 0.1461 0">
          <inertial pos="-0.0340053 -1.97613e-05 -0.0313192" quat="0.661985 -0.248547 -0.248547 0.661985" mass="0.85549" diaginertia="0.001717 0.00130207 0.00117493"/>
          <joint name="Continuous_2" pos="0 0 0" axis="-1 0 0" class="default_joint"/>
          <geom pos="-0.080264 -0.191277 -1.35004" class="cls" mesh="link_2" name="link_viz_2"/>
          <geom pos="-0.080264 -0.191277 -1.35004" class="viz" mesh="link_2" name="link_col_2"/>
          
          <body name="link_3" pos="-0.0315 -4.9e-05 -0.067">
            <inertial pos="-0.00565067 -0.00115717 -0.136754" quat="0.764363 0.0196959 0.0319099 0.643695" mass="4.51934" diaginertia="0.0412139 0.0409249 0.00378323"/>
            <joint name="Continuous_3" pos="0 0 0" axis="0 0.000738 1" class="default_joint"/>
            <geom pos="-0.048764 -0.191228 -1.28304" class="cls" mesh="link_3" name="link_viz_3"/>
            <geom pos="-0.048764 -0.191228 -1.28304" class="viz" mesh="link_3" name="link_col_3"/>
            
            <body name="link_4" pos="-0.02 0.031476 -0.235023">
              <inertial pos="0.0135327 -0.0370323 -0.025889" quat="0.717521 0.586142 -0.281824 0.249351" mass="0.599725" diaginertia="0.000990387 0.000800245 0.000566368"/>
              <joint name="Continuous_4" pos="0 0 0" axis="0 1 -0.000738" class="default_joint"/>
              <geom pos="-0.028764 -0.222704 -1.04802" class="cls" mesh="link_4" name="link_viz_4"/>
              <geom pos="-0.028764 -0.222704 -1.04802" class="viz" mesh="link_4" name="link_col_4"/>
              
              <body name="link_5" pos="0.019964 -0.034384 -0.04549">
                <inertial pos="-0.00144505 -0.000115861 -0.095562" quat="0.693428 0.00125175 0.00289369 0.720519" mass="3.57859" diaginertia="0.0188544 0.0186252 0.00280937"/>
                <joint name="Continuous_5" pos="0 0 0" axis="0.000798 0.000738 0.999999" class="default_joint"/>
                <geom pos="-0.048728 -0.18832 -1.00253" class="cls" mesh="link_5" name="link_viz_5"/>
                <geom pos="-0.048728 -0.18832 -1.00253" class="viz" mesh="link_5" name="link_col_5"/>
                
                <body name="link_6" pos="0.032301 -0.000184 -0.249526">
                  <inertial pos="-0.0326533 -0.0014376 0.000654463" quat="0.489442 0.51162 -0.515893 0.48223" mass="0.731528" diaginertia="0.000393336 0.000372011 0.000285653"/>
                  <joint name="Continuous_6" pos="0 0 0" axis="-1 -1e-06 -0.000798" class="default_joint"/>
                  <geom pos="-0.081029 -0.188136 -0.753006" class="cls" mesh="link_6" name="link_viz_6"/>
                  <geom pos="-0.081029 -0.188136 -0.753006" class="viz" mesh="link_6" name="link_col_6"/>
                  
                  <body name="link_7" pos="-0.0325 -0.0325 5e-05">
                    <inertial pos="-0.00030557 0.0242081 -0.0219" quat="0.732322 0.680958 0 0" mass="0.131342" diaginertia="9.8e-05 8.12183e-05 3.97817e-05"/>
                    <joint name="Continuous_7" pos="0 0 0" axis="0 -1 0.000738" class="default_joint"/>
                    <geom pos="-0.048529 -0.155636 -0.753056" class="cls" mesh="link_7" name="link_viz_7"/>
                    <geom pos="-0.048529 -0.155636 -0.753056" class="viz" mesh="link_7" name="link_col_7"/>
                  </body>
                </body>
              </body>
            </body>
          </body>
        </body>
      </body>
    </body>
  </worldbody>
</mujoco>
