<?xml version="1.0" ?>
<!-- =================================================================================== -->
<!-- |    This document was autogenerated by xacro from NewNew.xacro                   | -->
<!-- |    EDITING THIS FILE BY HAND IS NOT RECOMMENDED                                 | -->
<!-- =================================================================================== -->
<robot name="NewNew">
  <material name="silver">
    <color rgba="0.700 0.700 0.700 1.000"/>
  </material>
  <transmission name="Continuous_1_tran">
    <type>transmission_interface/SimpleTransmission</type>
    <joint name="Continuous_1">
      <hardwareInterface>hardware_interface/EffortJointInterface</hardwareInterface>
    </joint>
    <actuator name="Continuous_1_actr">
      <hardwareInterface>hardware_interface/EffortJointInterface</hardwareInterface>
      <mechanicalReduction>1</mechanicalReduction>
    </actuator>
  </transmission>
  <transmission name="Continuous_2_tran">
    <type>transmission_interface/SimpleTransmission</type>
    <joint name="Continuous_2">
      <hardwareInterface>hardware_interface/EffortJointInterface</hardwareInterface>
    </joint>
    <actuator name="Continuous_2_actr">
      <hardwareInterface>hardware_interface/EffortJointInterface</hardwareInterface>
      <mechanicalReduction>1</mechanicalReduction>
    </actuator>
  </transmission>
  <transmission name="Continuous_3_tran">
    <type>transmission_interface/SimpleTransmission</type>
    <joint name="Continuous_3">
      <hardwareInterface>hardware_interface/EffortJointInterface</hardwareInterface>
    </joint>
    <actuator name="Continuous_3_actr">
      <hardwareInterface>hardware_interface/EffortJointInterface</hardwareInterface>
      <mechanicalReduction>1</mechanicalReduction>
    </actuator>
  </transmission>
  <transmission name="Continuous_4_tran">
    <type>transmission_interface/SimpleTransmission</type>
    <joint name="Continuous_4">
      <hardwareInterface>hardware_interface/EffortJointInterface</hardwareInterface>
    </joint>
    <actuator name="Continuous_4_actr">
      <hardwareInterface>hardware_interface/EffortJointInterface</hardwareInterface>
      <mechanicalReduction>1</mechanicalReduction>
    </actuator>
  </transmission>
  <transmission name="Continuous_5_tran">
    <type>transmission_interface/SimpleTransmission</type>
    <joint name="Continuous_5">
      <hardwareInterface>hardware_interface/EffortJointInterface</hardwareInterface>
    </joint>
    <actuator name="Continuous_5_actr">
      <hardwareInterface>hardware_interface/EffortJointInterface</hardwareInterface>
      <mechanicalReduction>1</mechanicalReduction>
    </actuator>
  </transmission>
  <transmission name="Continuous_6_tran">
    <type>transmission_interface/SimpleTransmission</type>
    <joint name="Continuous_6">
      <hardwareInterface>hardware_interface/EffortJointInterface</hardwareInterface>
    </joint>
    <actuator name="Continuous_6_actr">
      <hardwareInterface>hardware_interface/EffortJointInterface</hardwareInterface>
      <mechanicalReduction>1</mechanicalReduction>
    </actuator>
  </transmission>
  <transmission name="Continuous_7_tran">
    <type>transmission_interface/SimpleTransmission</type>
    <joint name="Continuous_7">
      <hardwareInterface>hardware_interface/EffortJointInterface</hardwareInterface>
    </joint>
    <actuator name="Continuous_7_actr">
      <hardwareInterface>hardware_interface/EffortJointInterface</hardwareInterface>
      <mechanicalReduction>1</mechanicalReduction>
    </actuator>
  </transmission>
  <gazebo>
    <plugin filename="libgazebo_ros_control.so" name="control"/>
  </gazebo>
  <gazebo reference="base_link">
    <material>Gazebo/Silver</material>
    <mu1>0.2</mu1>
    <mu2>0.2</mu2>
    <selfCollide>true</selfCollide>
    <gravity>true</gravity>
  </gazebo>
  <gazebo reference="link1">
    <material>Gazebo/Silver</material>
    <mu1>0.2</mu1>
    <mu2>0.2</mu2>
    <selfCollide>true</selfCollide>
  </gazebo>
  <gazebo reference="link2">
    <material>Gazebo/Silver</material>
    <mu1>0.2</mu1>
    <mu2>0.2</mu2>
    <selfCollide>true</selfCollide>
  </gazebo>
  <gazebo reference="link3">
    <material>Gazebo/Silver</material>
    <mu1>0.2</mu1>
    <mu2>0.2</mu2>
    <selfCollide>true</selfCollide>
  </gazebo>
  <gazebo reference="link4">
    <material>Gazebo/Silver</material>
    <mu1>0.2</mu1>
    <mu2>0.2</mu2>
    <selfCollide>true</selfCollide>
  </gazebo>
  <gazebo reference="link5">
    <material>Gazebo/Silver</material>
    <mu1>0.2</mu1>
    <mu2>0.2</mu2>
    <selfCollide>true</selfCollide>
  </gazebo>
  <gazebo reference="link6">
    <material>Gazebo/Silver</material>
    <mu1>0.2</mu1>
    <mu2>0.2</mu2>
    <selfCollide>true</selfCollide>
  </gazebo>
  <gazebo reference="link7">
    <material>Gazebo/Silver</material>
    <mu1>0.2</mu1>
    <mu2>0.2</mu2>
    <selfCollide>true</selfCollide>
  </gazebo>
  <link name="base_link">
    <inertial>
      <origin rpy="0 0 0" xyz="0.04928686481333386 -0.015294922274216772 0.1793125700099067"/>
      <mass value="116.63982236647477"/>
      <inertia ixx="23.674952" ixy="-0.000131" ixz="0.017507" iyy="23.674748" iyz="-0.142193" izz="17.20743"/>
    </inertial>
    <visual>
      <origin rpy="0 0 0" xyz="0 0 0"/>
      <geometry>
        <mesh filename="package://NewNew_description/meshes/base_link.stl" scale="0.001 0.001 0.001"/>
      </geometry>
      <material name="silver"/>
    </visual>
    <collision>
      <origin rpy="0 0 0" xyz="0 0 0"/>
      <geometry>
        <mesh filename="package://NewNew_description/meshes/base_link.stl" scale="0.001 0.001 0.001"/>
      </geometry>
    </collision>
  </link>
  <link name="link1">
    <inertial>
      <origin rpy="0 0 0" xyz="0.00046041154110646604 0.08454149233959662 -9.53515480024425e-05"/>
      <mass value="8.373007278657763"/>
      <inertia ixx="0.031225" ixy="-0.000248" ixz="-1e-06" iyy="0.011605" iyz="-4.9e-05" izz="0.029319"/>
    </inertial>
    <visual>
      <origin rpy="0 0 0" xyz="-0.048764 -0.045177 -1.350045"/>
      <geometry>
        <mesh filename="package://NewNew_description/meshes/link1.stl" scale="0.001 0.001 0.001"/>
      </geometry>
      <material name="silver"/>
    </visual>
    <collision>
      <origin rpy="0 0 0" xyz="-0.048764 -0.045177 -1.350045"/>
      <geometry>
        <mesh filename="package://NewNew_description/meshes/link1.stl" scale="0.001 0.001 0.001"/>
      </geometry>
    </collision>
  </link>
  <link name="link2">
    <inertial>
      <origin rpy="0 0 0" xyz="-0.034005347626956214 -1.9761287684327833e-05 -0.03131916010199909"/>
      <mass value="0.8554896681537234"/>
      <inertia ixx="0.001247" ixy="0.0" ixz="6.3e-05" iyy="0.001717" iyz="-0.0" izz="0.00123"/>
    </inertial>
    <visual>
      <origin rpy="0 0 0" xyz="-0.080264 -0.191277 -1.350045"/>
      <geometry>
        <mesh filename="package://NewNew_description/meshes/link2.stl" scale="0.001 0.001 0.001"/>
      </geometry>
      <material name="silver"/>
    </visual>
    <collision>
      <origin rpy="0 0 0" xyz="-0.080264 -0.191277 -1.350045"/>
      <geometry>
        <mesh filename="package://NewNew_description/meshes/link2.stl" scale="0.001 0.001 0.001"/>
      </geometry>
    </collision>
  </link>
  <link name="link3">
    <inertial>
      <origin rpy="0 0 0" xyz="-0.005650672137827606 -0.0011571680272097207 -0.13675433838122264"/>
      <mass value="4.519343364177884"/>
      <inertia ixx="0.040729" ixy="1.8e-05" ixz="-0.002747" iyy="0.041201" iyz="-0.000413" izz="0.003992"/>
    </inertial>
    <visual>
      <origin rpy="0 0 0" xyz="-0.048764 -0.191228 -1.283045"/>
      <geometry>
        <mesh filename="package://NewNew_description/meshes/link3.stl" scale="0.001 0.001 0.001"/>
      </geometry>
      <material name="silver"/>
    </visual>
    <collision>
      <origin rpy="0 0 0" xyz="-0.048764 -0.191228 -1.283045"/>
      <geometry>
        <mesh filename="package://NewNew_description/meshes/link3.stl" scale="0.001 0.001 0.001"/>
      </geometry>
    </collision>
  </link>
  <link name="link4">
    <inertial>
      <origin rpy="0 0 0" xyz="0.013532735186533116 -0.03703231920714248 -0.025889023218529372"/>
      <mass value="0.5997248476129423"/>
      <inertia ixx="0.000895" ixy="-2.2e-05" ixz="9.9e-05" iyy="0.000575" iyz="3.9e-05" izz="0.000887"/>
    </inertial>
    <visual>
      <origin rpy="0 0 0" xyz="-0.028764 -0.222704 -1.048022"/>
      <geometry>
        <mesh filename="package://NewNew_description/meshes/link4.stl" scale="0.001 0.001 0.001"/>
      </geometry>
      <material name="silver"/>
    </visual>
    <collision>
      <origin rpy="0 0 0" xyz="-0.028764 -0.222704 -1.048022"/>
      <geometry>
        <mesh filename="package://NewNew_description/meshes/link4.stl" scale="0.001 0.001 0.001"/>
      </geometry>
    </collision>
  </link>
  <link name="link5">
    <inertial>
      <origin rpy="0 0 0" xyz="-0.001445047830852371 -0.0001158613699089317 -0.09556200573041573"/>
      <mass value="3.5785942066102105"/>
      <inertia ixx="0.018625" ixy="-9e-06" ixz="-9.2e-05" iyy="0.018854" iyz="-3.9e-05" izz="0.00281"/>
    </inertial>
    <visual>
      <origin rpy="0 0 0" xyz="-0.048728 -0.18832 -1.002532"/>
      <geometry>
        <mesh filename="package://NewNew_description/meshes/link5.stl" scale="0.001 0.001 0.001"/>
      </geometry>
      <material name="silver"/>
    </visual>
    <collision>
      <origin rpy="0 0 0" xyz="-0.048728 -0.18832 -1.002532"/>
      <geometry>
        <mesh filename="package://NewNew_description/meshes/link5.stl" scale="0.001 0.001 0.001"/>
      </geometry>
    </collision>
  </link>
  <link name="link6">
    <inertial>
      <origin rpy="0 0 0" xyz="-0.03265329885936323 -0.0014375954022153303 0.0006544633291232227"/>
      <mass value="0.7315278495451513"/>
      <inertia ixx="0.000372" ixy="-1e-06" ixz="0.0" iyy="0.000286" iyz="-6e-06" izz="0.000393"/>
    </inertial>
    <visual>
      <origin rpy="0 0 0" xyz="-0.081029 -0.188136 -0.753006"/>
      <geometry>
        <mesh filename="package://NewNew_description/meshes/link6.stl" scale="0.001 0.001 0.001"/>
      </geometry>
      <material name="silver"/>
    </visual>
    <collision>
      <origin rpy="0 0 0" xyz="-0.081029 -0.188136 -0.753006"/>
      <geometry>
        <mesh filename="package://NewNew_description/meshes/link6.stl" scale="0.001 0.001 0.001"/>
      </geometry>
    </collision>
  </link>
  <link name="link7">
    <inertial>
      <origin rpy="0 0 0" xyz="-0.00030557033531592587 0.024208131640507724 -0.02190001226772198"/>
      <mass value="0.1313418739393063"/>
      <inertia ixx="9.8e-05" ixy="0.0" ixz="-0.0" iyy="4e-05" iyz="3e-06" izz="8.1e-05"/>
    </inertial>
    <visual>
      <origin rpy="0 0 0" xyz="-0.048529 -0.155636 -0.753056"/>
      <geometry>
        <mesh filename="package://NewNew_description/meshes/link7.stl" scale="0.001 0.001 0.001"/>
      </geometry>
      <material name="silver"/>
    </visual>
    <collision>
      <origin rpy="0 0 0" xyz="-0.048529 -0.155636 -0.753056"/>
      <geometry>
        <mesh filename="package://NewNew_description/meshes/link7.stl" scale="0.001 0.001 0.001"/>
      </geometry>
    </collision>
  </link>
  <joint name="Continuous_1" type="continuous">
    <origin rpy="0 0 0" xyz="0.048764 0.045177 1.350045"/>
    <parent link="base_link"/>
    <child link="link1"/>
    <axis xyz="0.0 -1.0 -0.0"/>
  </joint>
  <joint name="Continuous_2" type="continuous">
    <origin rpy="0 0 0" xyz="0.0315 0.1461 0.0"/>
    <parent link="link1"/>
    <child link="link2"/>
    <axis xyz="1.0 -0.0 -0.0"/>
  </joint>
  <joint name="Continuous_3" type="continuous">
    <origin rpy="0 0 0" xyz="-0.0315 -4.9e-05 -0.067"/>
    <parent link="link2"/>
    <child link="link3"/>
    <axis xyz="-0.0 0.000738 1.0"/>
  </joint>
  <joint name="Continuous_4" type="continuous">
    <origin rpy="0 0 0" xyz="-0.02 0.031476 -0.235023"/>
    <parent link="link3"/>
    <child link="link4"/>
    <axis xyz="0.0 1.0 -0.000738"/>
  </joint>
  <joint name="Continuous_5" type="continuous">
    <origin rpy="0 0 0" xyz="0.019964 -0.034384 -0.04549"/>
    <parent link="link4"/>
    <child link="link5"/>
    <axis xyz="0.000798 0.000738 0.999999"/>
  </joint>
  <joint name="Continuous_6" type="continuous">
    <origin rpy="0 0 0" xyz="0.032301 -0.000184 -0.249526"/>
    <parent link="link5"/>
    <child link="link6"/>
    <axis xyz="1.0 -1e-06 -0.000798"/>
  </joint>
  <joint name="Continuous_7" type="continuous">
    <origin rpy="0 0 0" xyz="-0.0325 -0.0325 5e-05"/>
    <parent link="link6"/>
    <child link="link7"/>
    <axis xyz="-0.0 -1.0 0.000738"/>
  </joint>
</robot>

